<?xml version="1.0" ?>
<robot name="rover" xmlns:xacro="http://www.ros.org/wiki/xacro">

<xacro:include filename="$(find rover_description)/urdf/materials.xacro" />
<xacro:include filename="$(find rover_description)/urdf/rover.trans" />
<xacro:include filename="$(find rover_description)/urdf/rover.gazebo" />
<link name="base_link">
  <inertial>
    <origin xyz="0.0009227726591039774 0.012473118043377904 0.546498377628941" rpy="0 0 0"/>
    <mass value="10.783699848541888"/>
    <inertia ixx="0.758999" iyy="0.989152" izz="1.608633" ixy="0.007051" iyz="-0.000608" ixz="0.019853"/>
  </inertial>
  <visual>
    <origin xyz="0 0 0" rpy="0 0 0"/>
    <geometry>
      <mesh filename="file://$(find rover_description)/meshes/base_link.stl" scale="0.001 0.001 0.001"/>
    </geometry>
    <material name="silver"/>
  </visual>
  <collision>
    <origin xyz="0 0 0" rpy="0 0 0"/>
    <geometry>
      <mesh filename="file://$(find rover_description)/meshes/base_link.stl" scale="0.001 0.001 0.001"/>
    </geometry>
  </collision>
</link>

<link name="wheel_fl_1">
  <inertial>
    <origin xyz="-0.001529623664574653 -0.049976273019860185 7.113913612355471e-08" rpy="0 0 0"/>
    <mass value="0.3769911184307753"/>
    <inertia ixx="0.001257" iyy="0.001884" izz="0.001257" ixy="1.9e-05" iyz="0.0" ixz="-0.0"/>
  </inertial>
  <visual>
    <origin xyz="0.4418 0.336652 -0.094942" rpy="0 0 0"/>
    <geometry>
      <mesh filename="file://$(find rover_description)/meshes/wheel_fl_1.stl" scale="0.001 0.001 0.001"/>
    </geometry>
    <material name="silver"/>
  </visual>
  <collision>
    <origin xyz="0.4418 0.336652 -0.094942" rpy="0 0 0"/>
    <geometry>
      <mesh filename="file://$(find rover_description)/meshes/wheel_fl_1.stl" scale="0.001 0.001 0.001"/>
    </geometry>
  </collision>
</link>

<link name="wheel_ml_1">
  <inertial>
    <origin xyz="-0.0015300439854300657 -0.04997658968292701 -4.957345710182581e-07" rpy="0 0 0"/>
    <mass value="0.3769911184307754"/>
    <inertia ixx="0.001257" iyy="0.001884" izz="0.001257" ixy="1.9e-05" iyz="-0.0" ixz="0.0"/>
  </inertial>
  <visual>
    <origin xyz="-0.110438 0.378565 -0.102097" rpy="0 0 0"/>
    <geometry>
      <mesh filename="file://$(find rover_description)/meshes/wheel_ml_1.stl" scale="0.001 0.001 0.001"/>
    </geometry>
    <material name="silver"/>
  </visual>
  <collision>
    <origin xyz="-0.110438 0.378565 -0.102097" rpy="0 0 0"/>
    <geometry>
      <mesh filename="file://$(find rover_description)/meshes/wheel_ml_1.stl" scale="0.001 0.001 0.001"/>
    </geometry>
  </collision>
</link>

<link name="wheel_bl_1">
  <inertial>
    <origin xyz="-0.001529548606104103 -0.049976941390199814 -6.647671402237876e-08" rpy="0 0 0"/>
    <mass value="0.3769911184307753"/>
    <inertia ixx="0.001257" iyy="0.001884" izz="0.001257" ixy="1.9e-05" iyz="-0.0" ixz="0.0"/>
  </inertial>
  <visual>
    <origin xyz="-0.426338 0.388233 -0.104421" rpy="0 0 0"/>
    <geometry>
      <mesh filename="file://$(find rover_description)/meshes/wheel_bl_1.stl" scale="0.001 0.001 0.001"/>
    </geometry>
    <material name="silver"/>
  </visual>
  <collision>
    <origin xyz="-0.426338 0.388233 -0.104421" rpy="0 0 0"/>
    <geometry>
      <mesh filename="file://$(find rover_description)/meshes/wheel_bl_1.stl" scale="0.001 0.001 0.001"/>
    </geometry>
  </collision>
</link>

<link name="wheel_fr_1">
  <inertial>
    <origin xyz="0.001529146078766419 0.04997671728272385 3.6152866716987475e-07" rpy="0 0 0"/>
    <mass value="0.3769911184307751"/>
    <inertia ixx="0.001257" iyy="0.001884" izz="0.001257" ixy="1.9e-05" iyz="-0.0" ixz="0.0"/>
  </inertial>
  <visual>
    <origin xyz="0.423817 -0.387947 -0.099239" rpy="0 0 0"/>
    <geometry>
      <mesh filename="file://$(find rover_description)/meshes/wheel_fr_1.stl" scale="0.001 0.001 0.001"/>
    </geometry>
    <material name="silver"/>
  </visual>
  <collision>
    <origin xyz="0.423817 -0.387947 -0.099239" rpy="0 0 0"/>
    <geometry>
      <mesh filename="file://$(find rover_description)/meshes/wheel_fr_1.stl" scale="0.001 0.001 0.001"/>
    </geometry>
  </collision>
</link>

<link name="wheel_br_1">
  <inertial>
    <origin xyz="0.0015298161409178501 0.04997684645270012 1.6287605862641552e-07" rpy="0 0 0"/>
    <mass value="0.3769911184307751"/>
    <inertia ixx="0.001257" iyy="0.001884" izz="0.001257" ixy="1.9e-05" iyz="-0.0" ixz="0.0"/>
  </inertial>
  <visual>
    <origin xyz="-0.427778 -0.387095 -0.100462" rpy="0 0 0"/>
    <geometry>
      <mesh filename="file://$(find rover_description)/meshes/wheel_br_1.stl" scale="0.001 0.001 0.001"/>
    </geometry>
    <material name="silver"/>
  </visual>
  <collision>
    <origin xyz="-0.427778 -0.387095 -0.100462" rpy="0 0 0"/>
    <geometry>
      <mesh filename="file://$(find rover_description)/meshes/wheel_br_1.stl" scale="0.001 0.001 0.001"/>
    </geometry>
  </collision>
</link>

<link name="wheel_mr_1">
  <inertial>
    <origin xyz="0.0015291650076114105 0.049976107180178364 3.932498832126541e-08" rpy="0 0 0"/>
    <mass value="0.37699111843077493"/>
    <inertia ixx="0.001257" iyy="0.001884" izz="0.001257" ixy="1.9e-05" iyz="-0.0" ixz="0.0"/>
  </inertial>
  <visual>
    <origin xyz="-0.134622 -0.396068 -0.098894" rpy="0 0 0"/>
    <geometry>
      <mesh filename="file://$(find rover_description)/meshes/wheel_mr_1.stl" scale="0.001 0.001 0.001"/>
    </geometry>
    <material name="silver"/>
  </visual>
  <collision>
    <origin xyz="-0.134622 -0.396068 -0.098894" rpy="0 0 0"/>
    <geometry>
      <mesh filename="file://$(find rover_description)/meshes/wheel_mr_1.stl" scale="0.001 0.001 0.001"/>
    </geometry>
  </collision>
</link>

<link name="differential_bar_1">
  <inertial>
    <origin xyz="0.00029214245690140084 -8.53890068471658e-06 0.012496432720107031" rpy="0 0 0"/>
    <mass value="1.2065624999999998"/>
    <inertia ixx="0.051381" iyy="0.000209" izz="0.051465" ixy="-0.002069" iyz="1.2e-05" ixz="0.0"/>
  </inertial>
  <visual>
    <origin xyz="-0.418777 0.000316 -0.670253" rpy="0 0 0"/>
    <geometry>
      <mesh filename="file://$(find rover_description)/meshes/differential_bar_1.stl" scale="0.001 0.001 0.001"/>
    </geometry>
    <material name="silver"/>
  </visual>
  <collision>
    <origin xyz="-0.418777 0.000316 -0.670253" rpy="0 0 0"/>
    <geometry>
      <mesh filename="file://$(find rover_description)/meshes/differential_bar_1.stl" scale="0.001 0.001 0.001"/>
    </geometry>
  </collision>
</link>

<link name="rocker_right_1">
  <inertial>
    <origin xyz="-0.08875848398859393 0.03459512725062208 -0.14726629001580016" rpy="0 0 0"/>
    <mass value="0.06535699773789135"/>
    <inertia ixx="0.001491" iyy="0.004154" izz="0.002684" ixy="8.4e-05" iyz="3.9e-05" ixz="-0.001128"/>
  </inertial>
  <visual>
    <origin xyz="-0.019087 -0.329734 -0.513135" rpy="0 0 0"/>
    <geometry>
      <mesh filename="file://$(find rover_description)/meshes/rocker_right_1.stl" scale="0.001 0.001 0.001"/>
    </geometry>
    <material name="silver"/>
  </visual>
  <collision>
    <origin xyz="-0.019087 -0.329734 -0.513135" rpy="0 0 0"/>
    <geometry>
      <mesh filename="file://$(find rover_description)/meshes/rocker_right_1.stl" scale="0.001 0.001 0.001"/>
    </geometry>
  </collision>
</link>

<link name="rocker_left_1">
  <inertial>
    <origin xyz="-0.07326562920323927 -0.0546430812293327 -0.14840906678145804" rpy="0 0 0"/>
    <mass value="0.863831542999639"/>
    <inertia ixx="0.019809" iyy="0.054312" izz="0.03474" ixy="0.001023" iyz="0.000406" ixz="-0.015301"/>
  </inertial>
  <visual>
    <origin xyz="0.018249 0.279733 -0.513571" rpy="0 0 0"/>
    <geometry>
      <mesh filename="file://$(find rover_description)/meshes/rocker_left_1.stl" scale="0.001 0.001 0.001"/>
    </geometry>
    <material name="silver"/>
  </visual>
  <collision>
    <origin xyz="0.018249 0.279733 -0.513571" rpy="0 0 0"/>
    <geometry>
      <mesh filename="file://$(find rover_description)/meshes/rocker_left_1.stl" scale="0.001 0.001 0.001"/>
    </geometry>
  </collision>
</link>

<link name="bogie_left_1">
  <inertial>
    <origin xyz="-0.0037380262438453937 -0.01239141658757853 -0.10532183488933036" rpy="0 0 0"/>
    <mass value="0.9104202546563839"/>
    <inertia ixx="0.002289" iyy="0.013143" izz="0.010969" ixy="0.000332" iyz="4e-06" ixz="-0.00014"/>
  </inertial>
  <visual>
    <origin xyz="-0.272946 0.358527 -0.266244" rpy="0 0 0"/>
    <geometry>
      <mesh filename="file://$(find rover_description)/meshes/bogie_left_1.stl" scale="0.001 0.001 0.001"/>
    </geometry>
    <material name="silver"/>
  </visual>
  <collision>
    <origin xyz="-0.272946 0.358527 -0.266244" rpy="0 0 0"/>
    <geometry>
      <mesh filename="file://$(find rover_description)/meshes/bogie_left_1.stl" scale="0.001 0.001 0.001"/>
    </geometry>
  </collision>
</link>

<link name="bogie_right_1">
  <inertial>
    <origin xyz="-0.00465895004295469 0.012648710676595676 -0.10551209555340618" rpy="0 0 0"/>
    <mass value="0.8816303626402654"/>
    <inertia ixx="0.002211" iyy="0.013057" izz="0.010957" ixy="0.000332" iyz="-3e-06" ixz="0.0001"/>
  </inertial>
  <visual>
    <origin xyz="-0.297648 -0.366066 -0.258445" rpy="0 0 0"/>
    <geometry>
      <mesh filename="file://$(find rover_description)/meshes/bogie_right_1.stl" scale="0.001 0.001 0.001"/>
    </geometry>
    <material name="silver"/>
  </visual>
  <collision>
    <origin xyz="-0.297648 -0.366066 -0.258445" rpy="0 0 0"/>
    <geometry>
      <mesh filename="file://$(find rover_description)/meshes/bogie_right_1.stl" scale="0.001 0.001 0.001"/>
    </geometry>
  </collision>
</link>

<!--
<link name="support_left_1">
  <inertial>
    <origin xyz="0.20971490932691106 -0.020852392117456764 -0.00845410964047777" rpy="0 0 0"/>
    <mass value="0.24353234277329294"/>
    <inertia ixx="9e-06" iyy="0.003168" izz="0.003162" ixy="9e-06" iyz="-0.0" ixz="0.000142"/>
  </inertial>
  <visual>
    <origin xyz="0.015158 0.327284 -0.699176" rpy="0 0 0"/>
    <geometry>
      <mesh filename="file://$(find rover_description)/meshes/support_left_1.stl" scale="0.001 0.001 0.001"/>
    </geometry>
    <material name="silver"/>
  </visual>
  <collision>
    <origin xyz="0.015158 0.327284 -0.699176" rpy="0 0 0"/>
    <geometry>
      <mesh filename="file://$(find rover_description)/meshes/support_left_1.stl" scale="0.001 0.001 0.001"/>
    </geometry>
  </collision>
</link>
-->

<link name="support_left_1">
  <inertial>
    <origin xyz="-0.18766009067308892 0.008028607882543226 0.004245890359522275" rpy="0 0 0"/>
    <mass value="0.24353234277329294"/>
    <inertia ixx="9e-06" iyy="0.003168" izz="0.003162" ixy="9e-06" iyz="-0.0" ixz="0.000142"/>
  </inertial>
  <visual>
    <origin xyz="-0.382217 0.356165 -0.686476" rpy="0 0 0"/>
    <geometry>
      <mesh filename="file://$(find rover_description)/meshes/support_left_1.stl" scale="0.001 0.001 0.001"/>
    </geometry>
    <material name="silver"/>
  </visual>
  <collision>
    <origin xyz="-0.382217 0.356165 -0.686476" rpy="0 0 0"/>
    <geometry>
      <mesh filename="file://$(find rover_description)/meshes/support_left_1.stl" scale="0.001 0.001 0.001"/>
    </geometry>
  </collision>
</link>
<!--
<link name="support_right_1">
  <inertial>
    <origin xyz="-0.21910470807890262 0.0032160501765703398 0.0060783465928594405" rpy="0 0 0"/>
    <mass value="0.24661502330679955"/>
    <inertia ixx="2.1e-05" iyy="0.003277" izz="0.003284" ixy="0.000201" iyz="-8e-06" ixz="0.000133"/>
  </inertial>
  <visual>
    <origin xyz="-0.439843 -0.356508 -0.685477" rpy="0 0 0"/>
    <geometry>
      <mesh filename="file://$(find rover_description)/meshes/support_right_1.stl" scale="0.001 0.001 0.001"/>
    </geometry>
    <material name="silver"/>
  </visual>
  <collision>
    <origin xyz="-0.439843 -0.356508 -0.685477" rpy="0 0 0"/>
    <geometry>
      <mesh filename="file://$(find rover_description)/meshes/support_right_1.stl" scale="0.001 0.001 0.001"/>
    </geometry>
  </collision>
</link>
-->

<link name="support_right_1">
  <inertial>
    <origin xyz="0.18867429192109736 -0.016813949823429652 -0.007970653407140538" rpy="0 0 0"/>
    <mass value="0.24661502330679955"/>
    <inertia ixx="2.1e-05" iyy="0.003277" izz="0.003284" ixy="0.000201" iyz="-8e-06" ixz="0.000133"/>
  </inertial>
  <visual>
    <origin xyz="-0.032064 -0.376538 -0.699526" rpy="0 0 0"/>
    <geometry>
      <mesh filename="file://$(find rover_description)/meshes/support_right_1.stl" scale="0.001 0.001 0.001"/>
    </geometry>
    <material name="silver"/>
  </visual>
  <collision>
    <origin xyz="-0.032064 -0.376538 -0.699526" rpy="0 0 0"/>
    <geometry>
      <mesh filename="file://$(find rover_description)/meshes/support_right_1.stl" scale="0.001 0.001 0.001"/>
    </geometry>
  </collision>
</link>

<joint name="joint_wheel_fl" type="continuous">
  <origin xyz="-0.423551 -0.056919 -0.418629" rpy="0 0 0"/>
  <parent link="rocker_left_1"/>
  <child link="wheel_fl_1"/>
  <axis xyz="-0.030591 -0.999532 -0.0"/>
</joint>

<joint name="joint_wheel_ml" type="continuous">
  <origin xyz="-0.162508 -0.020038 -0.164147" rpy="0 0 0"/>
  <parent link="bogie_left_1"/>
  <child link="wheel_ml_1"/>
  <axis xyz="-0.030591 -0.999532 -0.0"/>
</joint>

<joint name="joint_wheel_bl" type="continuous">
  <origin xyz="0.153392 -0.029706 -0.161823" rpy="0 0 0"/>
  <parent link="bogie_left_1"/>
  <child link="wheel_bl_1"/>
  <axis xyz="-0.030591 -0.999532 -0.0"/>
</joint>

<joint name="joint_wheel_fr" type="continuous">
  <origin xyz="-0.442904 0.058213 -0.413896" rpy="0 0 0"/>
  <parent link="rocker_right_1"/>
  <child link="wheel_fr_1"/>
  <axis xyz="-0.030591 -0.999532 -0.0"/>
</joint>

<joint name="joint_wheel_mr" type="continuous">
  <origin xyz="0.13013 0.021029 -0.157983" rpy="0 0 0"/>
  <parent link="bogie_right_1"/>
  <child link="wheel_br_1"/>
  <axis xyz="0.030591 0.999532 0.0"/>
</joint>

<joint name="joint_wheel_br" type="continuous">
  <origin xyz="-0.163026 0.030002 -0.159551" rpy="0 0 0"/>
  <parent link="bogie_right_1"/>
  <child link="wheel_mr_1"/>
  <axis xyz="0.030591 0.999532 0.0"/>
</joint>

<joint name="joint_differential" type="continuous">
  <origin xyz="0.418777 -0.000316 0.670253" rpy="0 0 0"/>
  <parent link="base_link"/>
  <child link="differential_bar_1"/>
  <axis xyz="0.023347 -0.000715 0.999727"/>
</joint>

<joint name="joint_rocker_right" type="continuous">
  <origin xyz="0.019087 0.329734 0.513135" rpy="0 0 0"/>
  <parent link="base_link"/>
  <child link="rocker_right_1"/>
  <axis xyz="-0.030591 -0.999532 -0.0"/>
</joint>

<joint name="joint_rocker_left" type="continuous">
  <origin xyz="-0.018249 -0.279733 0.513571" rpy="0 0 0"/>
  <parent link="base_link"/>
  <child link="rocker_left_1"/>
  <axis xyz="-0.030591 -0.999532 -0.0"/>
</joint>

<joint name="joint_bogie_left" type="continuous">
  <origin xyz="0.291195 -0.078794 -0.247327" rpy="0 0 0"/>
  <parent link="rocker_left_1"/>
  <child link="bogie_left_1"/>
  <axis xyz="-0.030591 -0.999532 -0.0"/>
</joint>

<joint name="joint_bogie_right" type="continuous">
  <origin xyz="0.278561 0.036332 -0.25469" rpy="0 0 0"/>
  <parent link="rocker_right_1"/>
  <child link="bogie_right_1"/>
  <axis xyz="0.030591 0.999532 0.0"/>
</joint>

<joint name="joint_rocker_ball_left" type="fixed">
  <origin xyz="0.400466 -0.076432 0.172905" rpy="0 0 0"/>
  <parent link="rocker_left_1"/>
  <child link="support_left_1"/>
</joint>

<joint name="joint_diff_ball_left" type="fixed">
  <origin xyz="-0.03656 -0.355849 0.016223" rpy="0 0 0"/>
  <parent link="differential_bar_1"/>
  <child link="support_left_1"/>
</joint>

<joint name="joint_diff_ball_right" type="fixed">
  <origin xyz="-0.386713 0.376854 0.029273" rpy="0 0 0"/>
  <parent link="differential_bar_1"/>
  <child link="support_right_1"/>
</joint>

<joint name="joint_rocker_ball_right" type="fixed">
  <origin xyz="0.012977 0.046804 0.186391" rpy="0 0 0"/>
  <parent link="rocker_right_1"/>
  <child link="support_right_1"/>
</joint>

</robot>
