<robot name="rover">
  <material name="silver">
    <color rgba="0.75 0.75 0.75 1.0"/>
  </material>

  <link name="base_link">

    <inertial>
      <origin xyz="0 0 0" rpy="0 0 0"/>
      <mass value="10.783699848541888"/>
      <inertia
        ixx="0.4116"
        iyy="0.8034"
        izz="1.0141"
        ixy="0.0"
        ixz="0.0"
        iyz="0.0"/>
    </inertial>

    <visual>
      <origin xyz="0 0 0" rpy="0 0 0"/>
      <geometry>
        <box size="0.85 0.65 0.20"/>
      </geometry>
      <material name="silver"/>
    </visual>

    <collision>
      <origin xyz="0 0 0" rpy="0 0 0"/>
      <geometry>
        <box size="0.85 0.65 0.20"/>
      </geometry>
    </collision>

  </link>

  <link name="differential_bar_link">

  <inertial>
    <origin xyz="0 0 0.0125" rpy="0 0 0"/>
    <mass value="1.2065624999999998"/>
    <inertia
      ixx="0.0536"
      iyy="0.000063"
      izz="0.0536"
      ixy="0.0"
      ixz="0.0"
      iyz="0.0"/>
  </inertial>

  <visual>
    <origin xyz="0 0 0.0125" rpy="0 0 0"/>
    <geometry>
      <box size="0.025 0.73 0.025"/>
    </geometry>
    <material name="silver"/>
  </visual>

  <collision>
    <origin xyz="0 0 0.0125" rpy="0 0 0"/>
    <geometry>
      <box size="0.025 0.73 0.025"/>
    </geometry>
  </collision>

</link>

<link name="support_left_link">

  <inertial>
    <origin xyz="0.19375 0 0" rpy="0 1.57079632679 0"/>
    <mass value="0.24353234277329294"/>

    <inertia
      ixx="0.00001218"
      iyy="0.003050"
      izz="0.003050"
      ixy="0"
      ixz="0"
      iyz="0"/>
  </inertial>

  <visual>
    <origin xyz="0.19375 0 0" rpy="0 1.57079632679 0"/>

    <geometry>
      <cylinder radius="0.01" length="0.3875"/>
    </geometry>

    <material name="silver"/>
  </visual>

  <collision>
    <origin xyz="0.19375 0 0" rpy="0 1.57079632679 0"/>

    <geometry>
      <cylinder radius="0.01" length="0.3875"/>
    </geometry>
  </collision>

</link>


<link name="support_left_yaw_link">
  <inertial>
    <mass value="0.001"/>
    <origin xyz="0 0 0"/>
    <inertia ixx="1e-6" iyy="1e-6" izz="1e-6"
             ixy="0" ixz="0" iyz="0"/>
  </inertial>
</link>

<link name="support_right_yaw_link">
  <inertial>
    <mass value="0.001"/>
    <origin xyz="0 0 0"/>
    <inertia ixx="1e-6" iyy="1e-6" izz="1e-6"
             ixy="0" ixz="0" iyz="0"/>
  </inertial>
</link>

<link name="support_right_link">

  <inertial>
    <origin xyz="0.19375 0 0" rpy="0 1.57079632679 0"/>
    <mass value="0.24353234277329294"/>

    <inertia
      ixx="0.00001218"
      iyy="0.003050"
      izz="0.003050"
      ixy="0"
      ixz="0"
      iyz="0"/>
  </inertial>

  <visual>
    <origin xyz="0.19375 0 0" rpy="0 1.57079632679 0"/>

    <geometry>
      <cylinder radius="0.01" length="0.3875"/>
    </geometry>

    <material name="silver"/>
  </visual>

  <collision>
    <origin xyz="0.19375 0 0" rpy="0 1.57079632679 0"/>

    <geometry>
      <cylinder radius="0.01" length="0.3875"/>
    </geometry>
  </collision>

</link>

<link name="rocker_up_link_left">

  <inertial>
    <origin xyz="0 0 0.1" rpy="0 0 0"/>
    <mass value="0.330565"/>

    <inertia
      ixx="0.00112"
      iyy="0.00112"
      izz="0.0000344"
      ixy="0"
      ixz="0"
      iyz="0"/>
  </inertial>

  <visual>
    <origin xyz="0 0 0.1" rpy="0 0 0"/>

    <geometry>
      <box size="0.025 0.025 0.2"/>
    </geometry>

    <material name="silver"/>
  </visual>

  <collision>
    <origin xyz="0 0 0.1" rpy="0 0 0"/>

    <geometry>
      <box size="0.025 0.025 0.2"/>
    </geometry>
  </collision>

</link>

<link name="rocker_up_link_right">

  <inertial>
    <origin xyz="0 0 0.1" rpy="0 0 0"/>
    <mass value="0.330565"/>

    <inertia
      ixx="0.00112"
      iyy="0.00112"
      izz="0.0000344"
      ixy="0"
      ixz="0"
      iyz="0"/>
  </inertial>

  <visual>
    <origin xyz="0 0 0.1" rpy="0 0 0"/>

    <geometry>
      <box size="0.025 0.025 0.2"/>
    </geometry>

    <material name="silver"/>
  </visual>

  <collision>
    <origin xyz="0 0 0.1" rpy="0 0 0"/>

    <geometry>
      <box size="0.025 0.025 0.2"/>
    </geometry>
  </collision>

</link>

<link name="rocker_long_link_left">

  <inertial>
    <origin xyz="0.286 0 0" rpy="0 0 0"/>
    <mass value="0.945416"/>

    <inertia
      ixx="0.0000985"
      iyy="0.02581"
      izz="0.02581"
      ixy="0"
      ixz="0"
      iyz="0"/>
  </inertial>

  <visual>
    <origin xyz="0.286 0 0" rpy="0 0 0"/>

    <geometry>
      <box size="0.572 0.025 0.025"/>
    </geometry>

    <material name="silver"/>
  </visual>

  <collision>
    <origin xyz="0.286 0 0" rpy="0 0 0"/>

    <geometry>
      <box size="0.572 0.025 0.025"/>
    </geometry>
  </collision>

</link>

<link name="rocker_long_link_right">

  <inertial>
    <origin xyz="0.286 0 0" rpy="0 0 0"/>
    <mass value="0.945416"/>

    <inertia
      ixx="0.0000985"
      iyy="0.02581"
      izz="0.02581"
      ixy="0"
      ixz="0"
      iyz="0"/>
  </inertial>

  <visual>
    <origin xyz="0.286 0 0" rpy="0 0 0"/>

    <geometry>
      <box size="0.572 0.025 0.025"/>
    </geometry>

    <material name="silver"/>
  </visual>

  <collision>
    <origin xyz="0.286 0 0" rpy="0 0 0"/>

    <geometry>
      <box size="0.572 0.025 0.025"/>
    </geometry>
  </collision>

</link>

<link name="rocker_short_link_left">

  <inertial>
    <origin xyz="0.17 0 0" rpy="0 0 0"/>
    <mass value="0.56196"/>

    <inertia
      ixx="0.0000585"
      iyy="0.00548"
      izz="0.00548"
      ixy="0"
      ixz="0"
      iyz="0"/>
  </inertial>

  <visual>
    <origin xyz="0.17 0 0" rpy="0 0 0"/>

    <geometry>
      <box size="0.34 0.025 0.025"/>
    </geometry>

    <material name="silver"/>
  </visual>

  <collision>
    <origin xyz="0.17 0 0" rpy="0 0 0"/>

    <geometry>
      <box size="0.34 0.025 0.025"/>
    </geometry>
  </collision>

</link>

<link name="rocker_short_link_right">

  <inertial>
    <origin xyz="0.17 0 0" rpy="0 0 0"/>
    <mass value="0.56196"/>

    <inertia
      ixx="0.0000585"
      iyy="0.00548"
      izz="0.00548"
      ixy="0"
      ixz="0"
      iyz="0"/>
  </inertial>

  <visual>
    <origin xyz="0.17 0 0" rpy="0 0 0"/>

    <geometry>
      <box size="0.34 0.025 0.025"/>
    </geometry>

    <material name="silver"/>
  </visual>

  <collision>
    <origin xyz="0.17 0 0" rpy="0 0 0"/>

    <geometry>
      <box size="0.34 0.025 0.025"/>
    </geometry>
  </collision>

</link>

<link name="bogie_front_link_left">

  <inertial>
    <origin xyz="0.11575 0 0" rpy="0 0 0"/>
    <mass value="0.38246"/>

    <inertia
      ixx="0.0000310"
      iyy="0.00322"
      izz="0.00322"
      ixy="0"
      ixz="0"
      iyz="0"/>
  </inertial>

  <visual>
    <origin xyz="0.11575 0 0" rpy="0 0 0"/>

    <geometry>
      <box size="0.2315 0.025 0.025"/>
    </geometry>

    <material name="silver"/>
  </visual>

  <collision>
    <origin xyz="0.11575 0 0" rpy="0 0 0"/>

    <geometry>
      <box size="0.2315 0.025 0.025"/>
    </geometry>
  </collision>

</link>

<link name="bogie_mid_link_left">

  <inertial>
    <origin xyz="0.11575 0 0" rpy="0 0 0"/>
    <mass value="0.38246"/>

    <inertia
      ixx="0.0000310"
      iyy="0.00322"
      izz="0.00322"
      ixy="0"
      ixz="0"
      iyz="0"/>
  </inertial>

  <visual>
    <origin xyz="0.11575 0 0" rpy="0 0 0"/>

    <geometry>
      <box size="0.2315 0.025 0.025"/>
    </geometry>

    <material name="silver"/>
  </visual>

  <collision>
    <origin xyz="0.11575 0 0" rpy="0 0 0"/>

    <geometry>
      <box size="0.2315 0.025 0.025"/>
    </geometry>
  </collision>

</link>

<link name="bogie_mid_link_right">

  <inertial>
    <origin xyz="0.11575 0 0" rpy="0 0 0"/>
    <mass value="0.38246"/>

    <inertia
      ixx="0.0000310"
      iyy="0.00322"
      izz="0.00322"
      ixy="0"
      ixz="0"
      iyz="0"/>
  </inertial>

  <visual>
    <origin xyz="0.11575 0 0" rpy="0 0 0"/>

    <geometry>
      <box size="0.2315 0.025 0.025"/>
    </geometry>

    <material name="silver"/>
  </visual>

  <collision>
    <origin xyz="0.11575 0 0" rpy="0 0 0"/>

    <geometry>
      <box size="0.2315 0.025 0.025"/>
    </geometry>
  </collision>

</link>

<link name="bogie_front_link_right">

  <inertial>
    <origin xyz="0.11575 0 0" rpy="0 0 0"/>
    <mass value="0.38246"/>

    <inertia
      ixx="0.0000310"
      iyy="0.00322"
      izz="0.00322"
      ixy="0"
      ixz="0"
      iyz="0"/>
  </inertial>

  <visual>
    <origin xyz="0.11575 0 0" rpy="0 0 0"/>

    <geometry>
      <box size="0.2315 0.025 0.025"/>
    </geometry>

    <material name="silver"/>
  </visual>

  <collision>
    <origin xyz="0.11575 0 0" rpy="0 0 0"/>

    <geometry>
      <box size="0.2315 0.025 0.025"/>
    </geometry>
  </collision>

</link>


<link name="wheel_back_left_link">

  <inertial>
    <origin xyz="0 0 0" rpy="0 0 0"/>
    <mass value="0.37699111843077493"/>
    <inertia ixx="0.001" iyy="0.001" izz="0.001"
             ixy="0" ixz="0" iyz="0"/>
  </inertial>

  <visual>
    <geometry>
      <cylinder radius="0.1" length="0.1"/>
    </geometry>
    <material name="brown"/>
  </visual>

  <collision>
    <geometry>
      <cylinder radius="0.1" length="0.1"/>
    </geometry>
    <surface>
  <friction>
    <ode>
      <mu>1.2</mu>
      <mu2>1.2</mu2>
    </ode>
  </friction>

  <bounce>
    <restitution_coefficient>0.2</restitution_coefficient>
  </bounce>
</surface>
  </collision>

</link>

<link name="wheel_front_left_link">
  <inertial>
    <origin xyz="0 0 0" rpy="0 0 0"/>
    <mass value="0.37699111843077493"/>
    <inertia ixx="0.001" iyy="0.001" izz="0.001"
             ixy="0" ixz="0" iyz="0"/>
  </inertial>

  <visual>
    <geometry>
      <cylinder radius="0.1" length="0.1"/>
    </geometry>
    <material name="brown"/>
  </visual>

  <collision>
    <geometry>
      <cylinder radius="0.1" length="0.1"/>
    </geometry>
    <surface>
  <friction>
    <ode>
      <mu>1.2</mu>
      <mu2>1.2</mu2>
    </ode>
  </friction>

  <bounce>
    <restitution_coefficient>0.2</restitution_coefficient>
  </bounce>
</surface>
  </collision>
</link>

<link name="wheel_mid_left_link">
  <inertial>
    <origin xyz="0 0 0" rpy="0 0 0"/>
    <mass value="0.37699111843077493"/>
    <inertia ixx="0.001" iyy="0.001" izz="0.001"
             ixy="0" ixz="0" iyz="0"/>
  </inertial>

  <visual>
    <geometry>
      <cylinder radius="0.1" length="0.1"/>
    </geometry>
    <material name="brown"/>
  </visual>

  <collision>
    <geometry>
      <cylinder radius="0.1" length="0.1"/>
    </geometry>
    <surface>
  <friction>
    <ode>
      <mu>1.2</mu>
      <mu2>1.2</mu2>
    </ode>
  </friction>

  <bounce>
    <restitution_coefficient>0.2</restitution_coefficient>
  </bounce>
</surface>
  </collision>
</link>




<link name="wheel_back_right_link">

  <inertial>
    <origin xyz="0 0 0" rpy="0 0 0"/>
    <mass value="0.37699111843077493"/>
    <inertia ixx="0.001" iyy="0.001" izz="0.001"
             ixy="0" ixz="0" iyz="0"/>
  </inertial>

  <visual>
    <geometry>
      <cylinder radius="0.1" length="0.1"/>
    </geometry>
    <material name="brown"/>
  </visual>

  <collision>
    <geometry>
      <cylinder radius="0.1" length="0.1"/>
    </geometry>
    <surface>
  <friction>
    <ode>
      <mu>1.2</mu>
      <mu2>1.2</mu2>
    </ode>
  </friction>

  <bounce>
    <restitution_coefficient>0.2</restitution_coefficient>
  </bounce>
</surface>
  </collision>

</link>

<link name="wheel_front_right_link">
  <inertial>
    <origin xyz="0 0 0" rpy="0 0 0"/>
    <mass value="0.37699111843077493"/>
    <inertia ixx="0.001" iyy="0.001" izz="0.001"
             ixy="0" ixz="0" iyz="0"/>
  </inertial>

  <visual>
    <geometry>
      <cylinder radius="0.1" length="0.1"/>
    </geometry>
    <material name="brown"/>
  </visual>

  <collision>
    <geometry>
      <cylinder radius="0.1" length="0.1"/>
    </geometry>
    <surface>
  <friction>
    <ode>
      <mu>1.2</mu>
      <mu2>1.2</mu2>
    </ode>
  </friction>

  <bounce>
    <restitution_coefficient>0.2</restitution_coefficient>
  </bounce>
</surface>
  </collision>
</link>

<link name="wheel_mid_right_link">
  <inertial>
    <origin xyz="0 0 0" rpy="0 0 0"/>
    <mass value="0.37699111843077493"/>
    <inertia ixx="0.001" iyy="0.001" izz="0.001"
             ixy="0" ixz="0" iyz="0"/>
  </inertial>

  <visual>
    <geometry>
      <cylinder radius="0.1" length="0.1"/>
    </geometry>
    <material name="brown"/>
  </visual>

  <collision>
    <geometry>
      <cylinder radius="0.1" length="0.1"/>
    </geometry>
    <surface>
  <friction>
    <ode>
      <mu>1.2</mu>
      <mu2>1.2</mu2>
    </ode>
  </friction>

  <bounce>
    <restitution_coefficient>0.2</restitution_coefficient>
  </bounce>
</surface>
  </collision>
</link>


<joint name="wheel_back_right_joint" type="continuous">
  <parent link="rocker_long_link_right"/>
  <child link="wheel_back_right_link"/>
  <origin xyz="0.572 0 0" rpy="1.5708 -0.866 0"/>
  <axis xyz="0 0 -1"/>
</joint>

<joint name="wheel_front_right_joint" type="continuous">
  <parent link="bogie_front_link_right"/>
  <child link="wheel_front_right_link"/>
  <origin xyz="0.2315 0 0" rpy="1.5708 -0.866  0"/>
  <axis xyz="0 0 -1"/>
</joint>

<joint name="wheel_mid_right_joint" type="continuous">
  <parent link="bogie_mid_link_right"/>
  <child link="wheel_mid_right_link"/>
  <origin xyz="0.2315 0 0" rpy="1.5708 -0.866  0"/>
  <axis xyz="0 0 -1"/>
</joint>

<joint name="wheel_back_left_joint" type="continuous">
  <parent link="rocker_long_link_left"/>
  <child link="wheel_back_left_link"/>
  <origin xyz="0.572 0 0" rpy="1.5708 -0.866  0"/>
  <axis xyz="0 0 -1"/>
</joint>

<joint name="wheel_front_left_joint" type="continuous">
  <parent link="bogie_front_link_left"/>
  <child link="wheel_front_left_link"/>
  <origin xyz="0.2315 0 0" rpy="1.5708 -0.866  0"/>
  <axis xyz="0 0 -1"/>
</joint>

<joint name="wheel_mid_left_joint" type="continuous">
  <parent link="bogie_mid_link_left"/>
  <child link="wheel_mid_left_link"/>
  <origin xyz="0.2315 0 0" rpy="1.5708 -0.866  0"/>
  <axis xyz="0 0 -1"/>
</joint>



<joint name="bogie_right_joint" type="continuous">

  <parent link="rocker_short_link_right"/>
  <child link="bogie_front_link_right"/>

  <origin xyz="0.34 0 0" rpy="0 0 0"/>

  <axis xyz="0 1 0"/>
    <limit lower="-0.524" upper="0.524" effort="10" velocity="1"/>

</joint>

<joint name="bogie_mid_right_joint" type="fixed">

  <parent link="bogie_front_link_right"/>
  <child link="bogie_mid_link_right"/>

  <origin xyz="0 0 0" rpy="0 1.731925 0"/>

</joint>

<joint name="bogie__back_left_joint" type="fixed">

  <parent link="bogie_front_link_left"/>
  <child link="bogie_mid_link_left"/>

  <origin xyz="0 0 0" rpy="0 1.731925 0"/>

  <axis xyz="0 1 0"/>

</joint>


<joint name="bogie_left_joint" type="continuous">

  <parent link="rocker_short_link_left"/>
  <child link="bogie_front_link_left"/>

  <origin xyz="0.34 0 0" rpy="0 0 0"/>

  <axis xyz="0 1 0"/>
    <limit lower="-0.524" upper="0.524" effort="10" velocity="1"/>

</joint>




<joint name="rocker_long_right_fixed_joint" type="fixed">

  <parent link="rocker_up_link_right"/>
  <child link="rocker_long_link_right"/>

  <origin
      xyz="0 0 0"
      rpy="0 2.4368 0"/>

</joint>


<joint name="rocker_long_left_fixed_joint" type="fixed">

  <parent link="rocker_up_link_left"/>
  <child link="rocker_long_link_left"/>

  <origin
      xyz="0 0 0"
      rpy="0 2.4368 0"/>

</joint>

<joint name="rocker_short_right_fixed_joint" type="fixed">

  <parent link="rocker_up_link_right"/>
  <child link="rocker_short_link_right"/>

  <origin
      xyz="0 0 0"
      rpy="0 0.704836 0"/>

</joint>

<joint name="rocker_short_left_fixed_joint" type="fixed">

  <parent link="rocker_up_link_left"/>
  <child link="rocker_short_link_left"/>

  <origin
      xyz="0 0 0"
      rpy="0 0.704836 0"/>

</joint>

<joint name="rocker_left_base_joint" type="continuous">
  <parent link="base_link"/>
  <child link="rocker_up_link_left"/>

  <origin xyz="0 0.355 -.075" rpy="0 0 0"/>

  <axis xyz="0 1 0"/>
    <limit lower="-0.524" upper="0.524" effort="10" velocity="1"/>
</joint>

<joint name="rocker_right_base_joint" type="continuous">
  <parent link="base_link"/>
  <child link="rocker_up_link_right"/>

  <origin xyz="0 -0.355 -0.075" rpy="0 0 0"/>

  <axis xyz="0 1 0"/>
    <limit lower="-0.524" upper="0.524" effort="10" velocity="1"/>
</joint>

<joint name="support_right_yaw_joint" type="continuous">
  <parent link="differential_bar_link"/>
  <child link="support_right_yaw_link"/>

  <origin xyz="0.0125 -0.355 0.0125" rpy="0 0 0"/>

  <axis xyz="0 0 1"/>
    <limit lower="-0.524" upper="0.524" effort="10" velocity="1"/>
</joint>

<joint name="support_right_pitch_joint" type="continuous">
  <parent link="support_right_yaw_link"/>
  <child link="support_right_link"/>

  <origin xyz="0 0 0" rpy="0 0 0"/>

  <axis xyz="0 1 0"/>
    <limit lower="-0.524" upper="0.524" effort="10" velocity="1"/>
</joint>



<joint name="support_left_yaw_joint" type="continuous">
  <parent link="differential_bar_link"/>
  <child link="support_left_yaw_link"/>

  <origin xyz="0.0125 0.355 0.0125" rpy="0 0 0"/>

  <axis xyz="0 0 1"/>
    <limit lower="-0.524" upper="0.524" effort="10" velocity="1"/>
</joint>

<joint name="support_left_pitch_joint" type="continuous">
  <parent link="support_left_yaw_link"/>
  <child link="support_left_link"/>

  <origin xyz="0 0 0" rpy="0 0 0"/>

  <axis xyz="0 1 0"/>
    <limit lower="-0.524" upper="0.524" effort="10" velocity="1"/>
</joint>



<joint name="joint_differential" type="continuous">
  <parent link="base_link"/>
  <child link="differential_bar_link"/>

  <origin xyz="-0.42 0 0.10" rpy="0 0 0"/>

  <axis xyz="0 0 1"/>
    <limit lower="-0.3" upper="0.3" effort="10" velocity="1"/>
</joint>


<!-- ===== RGB-D Camera ===== -->
<link name="camera_link">
  <inertial>
    <origin xyz="0 0 0" rpy="0 0 0"/>
    <mass value="0.05"/>
    <inertia ixx="1e-5" iyy="1e-5" izz="1e-5"
             ixy="0" ixz="0" iyz="0"/>
  </inertial>
  <visual>
    <origin xyz="0 0 0" rpy="0 0 0"/>
    <geometry>
      <box size="0.04 0.10 0.03"/>
    </geometry>
    <material name="black">
      <color rgba="0.1 0.1 0.1 1.0"/>
    </material>
  </visual>
  <collision>
    <origin xyz="0 0 0" rpy="0 0 0"/>
    <geometry>
      <box size="0.04 0.10 0.03"/>
    </geometry>
  </collision>
</link>

<!-- optical frame: z forward, x right, y down — standard camera convention -->
<link name="camera_optical_link"/>

<joint name="camera_joint" type="fixed">
  <parent link="base_link"/>
  <child link="camera_link"/>
  <!-- 0.425 forward (x), 0.325 left (y), 0.1 up (z) from base_link centre,
       sitting on top of the chassis (chassis half-height = 0.10 m) -->
  <origin xyz="0.425 0 0.1" rpy="0 0 0"/>
</joint>

<!-- optical frame rotated so +Z points forward into the scene -->
<joint name="camera_optical_joint" type="fixed">
  <parent link="camera_link"/>
  <child link="camera_optical_link"/>
  <!-- standard ROS optical convention: roll -90°, yaw -90° -->
  <origin xyz="0 0 0" rpy="-1.5708 0 -1.5708"/>
</joint>

</robot>
